<?xml version="1.0" encoding="utf-8"?>
<!-- This URDF was automatically created by SolidWorks to URDF Exporter! Originally created by Stephen Brawner (brawner@gmail.com) 
     Commit Version: 1.6.0-4-g7f85cfe  Build Version: 1.6.7995.38578
     For more information, please see http://wiki.ros.org/sw_urdf_exporter -->
<robot
  name="arm_robot">
  <link name="world"/>
  <link
    name="base_link">
    <inertial>
      <origin
        xyz="-0.00013508 0.021215 0.0003347"
        rpy="0 0 0" />
      <mass
        value="0.85623" />
      <inertia
        ixx="0.0025365"
        ixy="-3.3034E-08"
        ixz="1.1719E-06"
        iyy="0.0050308"
        iyz="8.1853E-08"
        izz="0.0025341" />
    </inertial>
    <visual>
      <origin
        xyz="0 0 0"
        rpy="0 0 0" />
      <geometry>
        <mesh
          filename="package://arm_robot/meshes/base_link.STL" />
      </geometry>
      <material
        name="">
        <color
          rgba="0.79216 0.81961 0.93333 1" />
      </material>
    </visual>
    <collision>
      <origin
        xyz="0 0 0"
        rpy="0 0 0" />
      <geometry>
        <mesh
          filename="package://arm_robot/meshes/base_link.STL" />
      </geometry>
    </collision>
  </link>
  <joint name="base_joint" type="fixed">
  	<parent link="world"/>
  	<child link="base_link"/>
  	<origin xyz="0.0 0.0 0.0" rpy="1.57 0 0" />
  </joint>
  <link
    name="link1">
    <inertial>
      <origin
        xyz="0.0001723 0.010717 0.0033"
        rpy="0 0 0" />
      <mass
        value="0.17559" />
      <inertia
        ixx="0.00017251"
        ixy="1.0427E-06"
        ixz="8.7306E-07"
        iyy="0.00031357"
        iyz="-2.0249E-06"
        izz="0.00015248" />
    </inertial>
    <visual>
      <origin
        xyz="0 0 0"
        rpy="0 0 0" />
      <geometry>
        <mesh
          filename="package://arm_robot/meshes/link1.STL" />
      </geometry>
      <material
        name="">
        <color
          rgba="0.79216 0.81961 0.93333 1" />
      </material>
    </visual>
    <collision>
      <origin
        xyz="0 0 0"
        rpy="0 0 0" />
      <geometry>
        <mesh
          filename="package://arm_robot/meshes/link1.STL" />
      </geometry>
    </collision>
  </link>
  <joint
    name="joint1"
    type="revolute">
    <origin
      xyz="0 0.0653 0"
      rpy="0 1.4664 0" />
    <parent
      link="base_link" />
    <child
      link="link1" />
    <axis
      xyz="0 1 0" />
    <limit
      lower="0"
      upper="3.142"
      effort="3"
      velocity="4" />
  </joint>
  <link
    name="link2">
    <inertial>
      <origin
        xyz="0.0028854 -0.037657 0.02116"
        rpy="0 0 0" />
      <mass
        value="0.029075" />
      <inertia
        ixx="3.2099E-05"
        ixy="-3.0364E-09"
        ixz="1.3417E-09"
        iyy="8.7678E-06"
        iyz="1.2187E-05"
        izz="2.3608E-05" />
    </inertial>
    <visual>
      <origin
        xyz="0 0 0"
        rpy="0 0 0" />
      <geometry>
        <mesh
          filename="package://arm_robot/meshes/link2.STL" />
      </geometry>
      <material
        name="">
        <color
          rgba="0.79216 0.81961 0.93333 1" />
      </material>
    </visual>
    <collision>
      <origin
        xyz="0 0 0"
        rpy="0 0 0" />
      <geometry>
        <mesh
          filename="package://arm_robot/meshes/link2.STL" />
      </geometry>
    </collision>
  </link>
  <joint
    name="joint2"
    type="revolute">
    <origin
      xyz="0 0.0229 0.00043961"
      rpy="0.51193 0 3.1416" />
    <parent
      link="link1" />
    <child
      link="link2" />
    <axis
      xyz="-1 0 0" />
    <limit
      lower="-1.57"
      upper="1.57"
      effort="3"
      velocity="4" />
  </joint>
  <link
    name="link3">
    <inertial>
      <origin
        xyz="0.039018 -1.5837E-05 0.00013351"
        rpy="0 0 0" />
      <mass
        value="0.077386" />
      <inertia
        ixx="8.8164E-06"
        ixy="6.2986E-08"
        ixz="-1.6053E-06"
        iyy="6.4568E-05"
        iyz="-4.7787E-10"
        izz="6.301E-05" />
    </inertial>
    <visual>
      <origin
        xyz="0 0 0"
        rpy="0 0 0" />
      <geometry>
        <mesh
          filename="package://arm_robot/meshes/link3.STL" />
      </geometry>
      <material
        name="">
        <color
          rgba="0.79216 0.81961 0.93333 1" />
      </material>
    </visual>
    <collision>
      <origin
        xyz="0 0 0"
        rpy="0 0 0" />
      <geometry>
        <mesh
          filename="package://arm_robot/meshes/link3.STL" />
      </geometry>
    </collision>
  </link>
  <joint
    name="joint3"
    type="revolute">
    <origin
      xyz="0 -0.075315 0.042319"
      rpy="1.5708 -0.51193 -1.5708" />
    <parent
      link="link2" />
    <child
      link="link3" />
    <axis
      xyz="0 0 1" />
    <limit
      lower="-1.57"
      upper="1.57"
      effort="3"
      velocity="4" />
  </joint>
  <link
    name="link4">
    <inertial>
      <origin
        xyz="0.075718 0.0078323 -0.0023511"
        rpy="0 0 0" />
      <mass
        value="0.12848" />
      <inertia
        ixx="3.7512E-05"
        ixy="-2.5961E-08"
        ixz="3.1447E-06"
        iyy="5.7704E-05"
        iyz="-9.6946E-09"
        izz="3.5473E-05" />
    </inertial>
    <visual>
      <origin
        xyz="0 0 0"
        rpy="0 0 0" />
      <geometry>
        <mesh
          filename="package://arm_robot/meshes/link4.STL" />
      </geometry>
      <material
        name="">
        <color
          rgba="0.79216 0.81961 0.93333 1" />
      </material>
    </visual>
    <collision>
      <origin
        xyz="0 0 0"
        rpy="0 0 0" />
      <geometry>
        <mesh
          filename="package://arm_robot/meshes/link4.STL" />
      </geometry>
    </collision>
  </link>
  <joint
    name="joint4"
    type="revolute">
    <origin
      xyz="0.1181 0 0"
      rpy="0 0 0" />
    <parent
      link="link3" />
    <child
      link="link4" />
    <axis
      xyz="0 0 1" />
    <limit
      lower="-1.57"
      upper="1.57"
      effort="3"
      velocity="4" />
  </joint>
  <link
    name="link5">
    <inertial>
      <origin
        xyz="0.027123 0.00037494 0.039116"
        rpy="0 0 0" />
      <mass
        value="0.01684" />
      <inertia
        ixx="4.0476E-06"
        ixy="-6.256E-08"
        ixz="-2.0534E-06"
        iyy="5.368E-06"
        iyz="-1.0318E-07"
        izz="1.9876E-06" />
    </inertial>
    <visual>
      <origin
        xyz="0 0 0"
        rpy="0 0 0" />
      <geometry>
        <mesh
          filename="package://arm_robot/meshes/link5.STL" />
      </geometry>
      <material
        name="">
        <color
          rgba="0.79216 0.81961 0.93333 1" />
      </material>
    </visual>
    <collision>
      <origin
        xyz="0 0 0"
        rpy="0 0 0" />
      <geometry>
        <mesh
          filename="package://arm_robot/meshes/link5.STL" />
      </geometry>
    </collision>
  </link>
  <joint
    name="joint5"
    type="revolute">
    <origin
      xyz="0.11993 0 0.012424"
      rpy="-3.1112 -0.89161 0" />
    <parent
      link="link4" />
    <child
      link="link5" />
    <axis
      xyz="0 1 0" />
    <limit
      lower="0"
      upper="1.57"
      effort="1"
      velocity="4" />
  </joint>
  <link
    name="link6">
    <inertial>
      <origin
        xyz="-0.023433 8.3598E-05 0.030623"
        rpy="0 0 0" />
      <mass
        value="0.021692" />
      <inertia
        ixx="4.4063E-06"
        ixy="7.7606E-08"
        ixz="2.5426E-06"
        iyy="6.5097E-06"
        iyz="-1.1332E-07"
        izz="2.7995E-06" />
    </inertial>
    <visual>
      <origin
        xyz="0 0 0"
        rpy="0 0 0" />
      <geometry>
        <mesh
          filename="package://arm_robot/meshes/link6.STL" />
      </geometry>
      <material
        name="">
        <color
          rgba="0.79216 0.81961 0.93333 1" />
      </material>
    </visual>
    <collision>
      <origin
        xyz="0 0 0"
        rpy="0 0 0" />
      <geometry>
        <mesh
          filename="package://arm_robot/meshes/link6.STL" />
      </geometry>
    </collision>
  </link>
  <joint
    name="joint6"
    type="revolute">
    <origin
      xyz="0.11993 0 -0.015576"
      rpy="0.030391 -0.81089 -3.1416" />
    <parent
      link="link4" />
    <child
      link="link6" />
    <axis
      xyz="0 1 0" />
    <limit
      lower="-1.57"
      upper="0"
      effort="1"
      velocity="4" />
  </joint>
  <!-- Virtual roll joint -->
  <joint name="virtual_roll_joint" type="revolute">
    <limit lower="-3.1415" upper="3.1415" effort="54.0" velocity="4"/>
    <parent link="link4"/>
    <child link="virtual_roll_link"/>
    <axis xyz="1 0 0"/>
    <origin xyz="0.2056 0.0 0.0" rpy="0 0 0"/>
    <dynamics damping="0.0" friction="0.0"/>
  </joint>

  <!-- Virtual roll link -->
  <link name="virtual_roll_link">
    <visual>
      <origin xyz="0 0 0" rpy="0 0 0"/>
      <geometry>
        <box size="0.001 0.001 0.001" />
      </geometry>
     </visual>

    <inertial>
      <origin xyz="0 0 0" />
      <mass value="1.0e-03" />
      <inertia ixx="1.0e-03" ixy="0.0" ixz="0.0"
               iyy="1.0e-03" iyz="0.0"
               izz="1.0e-03" />
    </inertial>
  </link>

  <gazebo reference="virtual_roll_link">
  </gazebo>

  <!-- Virtual yaw joint -->
  <joint name="virtual_yaw_joint" type="revolute">
    <limit lower="-3.1415" upper="3.1415" effort="54.0" velocity="4"/>
    <parent link="virtual_roll_link"/>
    <child link="virtual_yaw_link"/>
    <axis xyz="0 0 1"/>
    <origin xyz="0.0 0.0 0.0" rpy="0 0 0"/>
    <dynamics damping="0.0" friction="0.0"/>
  </joint>

  <!-- Virtual yaw link -->
  <link name="virtual_yaw_link">
    <visual>
      <origin xyz="0 0 0" rpy="0 0 0"/>
      <geometry>
        <box size="0.001 0.001 0.001" />
      </geometry>
     </visual>

    <inertial>
      <origin xyz="0 0 0" />
      <mass value="1.0e-03" />
      <inertia ixx="1.0e-03" ixy="0.0" ixz="0.0"
               iyy="1.0e-03" iyz="0.0"
               izz="1.0e-03" />
    </inertial>
  </link>
  <gazebo reference="virtual_yaw_link">
  </gazebo>
  
  <!-- end effector joint -->
  <link name="gripper_center">
    <visual>
      <origin xyz="0 0 0" rpy="0 0 0"/>
     </visual>
  </link>
  <joint name="gripper_center_joint" type="fixed">
    <parent link="virtual_yaw_link"/>
    <child link="gripper_center"/>
    <origin xyz="0.0 0.0 0.0" rpy="0.0 0.0 0.0" />
  </joint>

  <transmission name="link1_trans">
    <type>transmission_interface/SimpleTransmission</type>
    <joint name="joint1">
      <hardwareInterface>hardware_interface/PositionJointInterface</hardwareInterface>
    </joint>
    <actuator name="link1_motor">
      <hardwareInterface>hardware_interface/PositionJointInterface</hardwareInterface>
      <mechanicalReduction>1</mechanicalReduction>
    </actuator>
  </transmission>
  <transmission name="link2_trans">
    <type>transmission_interface/SimpleTransmission</type>
    <joint name="joint2">
      <hardwareInterface>hardware_interface/PositionJointInterface</hardwareInterface>
    </joint>
    <actuator name="link2_motor">
      <hardwareInterface>hardware_interface/PositionJointInterface</hardwareInterface>
      <mechanicalReduction>1</mechanicalReduction>
    </actuator>
  </transmission>
  <transmission name="link3_trans">
    <type>transmission_interface/SimpleTransmission</type>
    <joint name="joint3">
      <hardwareInterface>hardware_interface/PositionJointInterface</hardwareInterface>
    </joint>
    <actuator name="link3_motor">
      <hardwareInterface>hardware_interface/PositionJointInterface</hardwareInterface>
      <mechanicalReduction>1</mechanicalReduction>
    </actuator>
  </transmission>
  <transmission name="link4_trans">
    <type>transmission_interface/SimpleTransmission</type>
    <joint name="joint4">
      <hardwareInterface>hardware_interface/PositionJointInterface</hardwareInterface>
    </joint>
    <actuator name="link4_motor">
      <hardwareInterface>hardware_interface/PositionJointInterface</hardwareInterface>
      <mechanicalReduction>1</mechanicalReduction>
    </actuator>
  </transmission>
  <transmission name="link5_trans">
    <type>transmission_interface/SimpleTransmission</type>
    <joint name="joint5">
      <hardwareInterface>hardware_interface/PositionJointInterface</hardwareInterface>
    </joint>
    <actuator name="link5_motor">
      <hardwareInterface>hardware_interface/PositionJointInterface</hardwareInterface>
      <mechanicalReduction>1</mechanicalReduction>
    </actuator>
  </transmission>
  <transmission name="link6_trans">
    <type>transmission_interface/SimpleTransmission</type>
    <joint name="joint6">
      <hardwareInterface>hardware_interface/PositionJointInterface</hardwareInterface>
    </joint>
    <actuator name="link6_motor">
      <hardwareInterface>hardware_interface/PositionJointInterface</hardwareInterface>
      <mechanicalReduction>1</mechanicalReduction>
    </actuator>
  </transmission>
  <transmission name="virtual_roll_joint_trans">
    <type>transmission_interface/SimpleTransmission</type>
    <joint name="virtual_roll_joint">
      <hardwareInterface>hardware_interface/PositionJointInterface</hardwareInterface>
    </joint>
    <actuator name="virtual_roll_joint_motor">
      <hardwareInterface>hardware_interface/PositionJointInterface</hardwareInterface>
      <mechanicalReduction>1</mechanicalReduction>
    </actuator>
  </transmission>
  <transmission name="virtual_yaw_joint_trans">
    <type>transmission_interface/SimpleTransmission</type>
    <joint name="virtual_yaw_joint">
      <hardwareInterface>hardware_interface/PositionJointInterface</hardwareInterface>
    </joint>
    <actuator name="virtual_yaw_joint_motor">
      <hardwareInterface>hardware_interface/PositionJointInterface</hardwareInterface>
      <mechanicalReduction>1</mechanicalReduction>
    </actuator>
  </transmission>
  <gazebo>
    <plugin name="control" filename="libgazebo_ros_control.so">
      <robotNamespace>/</robotNamespace>
    </plugin>
  </gazebo>
  <gazebo reference="link1">
    <selfCollide>true</selfCollide>
  </gazebo>
  <gazebo reference="link2">
    <selfCollide>true</selfCollide>
  </gazebo>
  <gazebo reference="link3">
    <selfCollide>true</selfCollide>
  </gazebo>
  <gazebo reference="link4">
    <selfCollide>true</selfCollide>
  </gazebo>
  <gazebo reference="link5">
    <selfCollide>true</selfCollide>
  </gazebo>
  <gazebo reference="link6">
    <selfCollide>true</selfCollide>
  </gazebo>
</robot>
